<?xml version="1.0" encoding="utf-8"?>
<robot
  name="bot">
  <link
    name="base_link">
    <inertial>
      <origin
        xyz="0 0 0"
        rpy="0 0 0" />
      <mass
        value="15.168" />
      <inertia
        ixx="0.37884"
        ixy="-6.3135E-17"
        ixz="0.012125"
        iyy="0.41552"
        iyz="-1.136E-17"
        izz="0.789" />
    </inertial>
    <visual>
      <origin
        xyz="0 0 0"
        rpy="0 0 0" />
      <geometry>
        <mesh
          filename="package://bot/meshes/base_link.STL" />
      </geometry>
      <material
        name="">
        <color
          rgba="0.79216 0.81961 0.93333 1" />
      </material>
    </visual>
    <collision>
      <origin
        xyz="0 0 0"
        rpy="0 0 0" />
      <geometry>
        <mesh
          filename="package://bot/meshes/base_link.STL" />
      </geometry>
    </collision>
  </link>
  <gazebo reference="base_link">
    <material>Gazebo/White</material>
    <mu1>0.2</mu1>
    <mu2>0.2</mu2>
    <selfCollide>true</selfCollide>
  </gazebo>
  <link
    name="link_1">
    <inertial>
      <origin
        xyz="3.8752E-11 1.9819E-11 0.0375"
        rpy="0 0 0" />
      <mass
        value="0.3649" />
      <inertia
        ixx="0.00028262"
        ixy="1.4029E-12"
        ixz="9.1655E-13"
        iyy="0.00028262"
        iyz="2.1972E-12"
        izz="0.00038229" />
    </inertial>
    <visual>
      <origin
        xyz="0 0 0"
        rpy="0 0 0" />
      <geometry>
        <mesh
          filename="package://bot/meshes/link_1.STL" />
      </geometry>
      <material
        name="">
        <color
          rgba="0.79216 0.81961 0.93333 1" />
      </material>
    </visual>
    <collision>
      <origin
        xyz="0 0 0"
        rpy="0 0 0" />
      <geometry>
        <mesh
          filename="package://bot/meshes/link_1.STL" />
      </geometry>
    </collision>
  </link>
  <gazebo reference="link_1">
    <material>Gazebo/Black</material>
    <mu1>15000</mu1>
    <mu2>15000</mu2>
    <selfCollide>true</selfCollide>
  </gazebo>
  <joint
    name="joint_1"
    type="continuous">
    <origin
      xyz="-0.02405 -0.2545 0.025915"
      rpy="-1.5708 0.037304 0" />
    <parent
      link="base_link" />
    <child
      link="link_1" />
    <axis
      xyz="0 0 1" />
    <limit
      effort="100"
      velocity="100" />
  </joint>
  <link
    name="link_2">
    <inertial>
      <origin
        xyz="4.5793E-11 -4.5064E-11 -0.0375"
        rpy="0 0 0" />
      <mass
        value="0.3649" />
      <inertia
        ixx="0.00028262"
        ixy="-3.5655E-13"
        ixz="1.6795E-12"
        iyy="0.00028262"
        iyz="-2.3287E-12"
        izz="0.00038229" />
    </inertial>
    <visual>
      <origin
        xyz="0 0 0"
        rpy="0 0 0" />
      <geometry>
        <mesh
          filename="package://bot/meshes/link_2.STL" />
      </geometry>
      <material
        name="">
        <color
          rgba="0.79216 0.81961 0.93333 1" />
      </material>
    </visual>
    <collision>
      <origin
        xyz="0 0 0"
        rpy="0 0 0" />
      <geometry>
        <mesh
          filename="package://bot/meshes/link_2.STL" />
      </geometry>
    </collision>
  </link>
  <gazebo reference="link_2">
    <material>Gazebo/Black</material>
     <mu1>15000</mu1>
    <mu2>15000</mu2>
    <selfCollide>true</selfCollide>
  </gazebo>
  <joint
    name="joint_2"
    type="continuous">
    <origin
      xyz="-0.02405 0.255 0.025915"
      rpy="-1.5708 0.037304 0" />
    <parent
      link="base_link" />
    <child
      link="link_2" />
    <axis
      xyz="0 0 1" />
    <limit
      effort="100"
      velocity="100" />
  </joint>
  <link
    name="link_3">
    <inertial>
      <origin
        xyz="3.8963E-10 2.7669E-10 -0.15509"
        rpy="0 0 0" />
      <mass
        value="0.25923" />
      <inertia
        ixx="0.0019313"
        ixy="1.7325E-10"
        ixz="1.2282E-09"
        iyy="0.0019313"
        iyz="-3.8798E-10"
        izz="4.3605E-05" />
    </inertial>
    <visual>
      <origin
        xyz="0 0 0"
        rpy="0 0 0" />
      <geometry>
        <mesh
          filename="package://bot/meshes/link_3.STL" />
      </geometry>
      <material
        name="">
        <color
          rgba="0.79608 0.82353 0.93725 1" />
      </material>
    </visual>
    <collision>
      <origin
        xyz="0 0 0"
        rpy="0 0 0" />
      <geometry>
        <mesh
          filename="package://bot/meshes/link_3.STL" />
      </geometry>
    </collision>
  </link>
  <gazebo reference="link_3">
    <material>Gazebo/Red</material>
     <mu1>0.2</mu1>
    <mu2>0.2</mu2>
    <selfCollide>true</selfCollide>
  </gazebo>
  <joint
    name="joint_3"
    type="continuous">
    <origin
      xyz="-0.034319 -0.155 0.026298"
      rpy="1.5708 0.037304 0" />
    <parent
      link="base_link" />
    <child
      link="link_3" />
    <axis
      xyz="0 0 1" />
    <limit
      effort="100"
      velocity="100" />
  </joint>
  <link
    name="link_4">
    <inertial>
      <origin
        xyz="6.095E-09 -1.091E-08 -0.029197"
        rpy="0 0 0" />
      <mass
        value="0.10253" />
      <inertia
        ixx="3.468E-05"
        ixy="1.2555E-10"
        ixz="-1.2705E-11"
        iyy="3.468E-05"
        iyz="2.2742E-11"
        izz="3.439E-05" />
    </inertial>
    <visual>
      <origin
        xyz="0 0 0"
        rpy="0 0 0" />
      <geometry>
        <mesh
          filename="package://bot/meshes/link_4.STL" />
      </geometry>
      <material
        name="">
        <color
          rgba="0.79216 0.81961 0.93333 1" />
      </material>
    </visual>
    <collision>
      <origin
        xyz="0 0 0"
        rpy="0 0 0" />
      <geometry>
        <mesh
          filename="package://bot/meshes/link_4.STL" />
      </geometry>
    </collision>
  </link>
  <gazebo reference="link_4">
    <material>Gazebo/Black</material>
     <mu1>15000</mu1>
    <mu2>15000</mu2>
    <selfCollide>true</selfCollide>
  </gazebo>
  <joint
    name="joint_4"
    type="continuous">
    <origin
      xyz="0.2185 0 0.022867"
      rpy="0 0.037304 0" />
    <parent
      link="base_link" />
    <child
      link="link_4" />
    <axis
      xyz="0 0 1" />
    <limit
      effort="100"
      velocity="100" />
  </joint>
  <link
    name="link_5">
    <inertial>
      <origin
        xyz="0.0042516 3.4761E-18 0.11392"
        rpy="0 0 0" />
      <mass
        value="0.46181" />
      <inertia
        ixx="0.0006011"
        ixy="2.6833E-20"
        ixz="1.9793E-05"
        iyy="0.00060036"
        iyz="-7.7824E-21"
        izz="0.0011307" />
    </inertial>
    <visual>
      <origin
        xyz="0 0 0"
        rpy="0 0 0" />
      <geometry>
        <mesh
          filename="package://bot/meshes/link_5.STL" />
      </geometry>
      <material
        name="">
        <color
          rgba="0.79216 0.81961 0.93333 1" />
      </material>
    </visual>
    <collision>
      <origin
        xyz="0 0 0"
        rpy="0 0 0" />
      <geometry>
        <mesh
          filename="package://bot/meshes/link_5.STL" />
      </geometry>
    </collision>
  </link>
  <gazebo reference="link_5">
    <material>Gazebo/Black</material>
     <mu1>0.2</mu1>
    <mu2>0.2</mu2>
    <selfCollide>true</selfCollide>
  </gazebo>
  <joint
    name="joint_5"
    type="fixed">
    <origin
      xyz="0 0 0"
      rpy="0 0 0" />
    <parent
      link="base_link" />
    <child
      link="link_5" />
    <axis
      xyz="0 0 0" />
  </joint>
  
  <gazebo>
  <plugin name="differential_drive_controller" filename="libgazebo_ros_diff_drive.so">

    <!-- Plugin update rate in Hz -->
    <updateRate>10</updateRate>

    <!-- Name of left joint, defaults to `left_joint` -->
    <leftJoint>joint_2</leftJoint>

    <!-- Name of right joint, defaults to `right_joint` -->
    <rightJoint>joint_1</rightJoint>

    <!-- The distance from the center of one wheel to the other, in meters, defaults to 0.34 m -->
    <wheelSeparation>0.435</wheelSeparation>

    <!-- Diameter of the wheels, in meters, defaults to 0.15 m -->
    <wheelDiameter>0.1054</wheelDiameter>

    <!-- Wheel acceleration, in rad/s^2, defaults to 0.0 rad/s^2 -->
    <wheelAcceleration>1.0</wheelAcceleration>

    <!-- Maximum torque which the wheels can produce, in Nm, defaults to 5 Nm -->
    <wheelTorque>30</wheelTorque>

    <!-- Topic to receive geometry_msgs/Twist message commands, defaults to `cmd_vel` -->
    <commandTopic>cmd_vel</commandTopic>

    <!-- Topic to publish nav_msgs/Odometry messages, defaults to `odom` -->
    <odometryTopic>odom</odometryTopic>

    <!-- Odometry frame, defaults to `odom` -->
    <odometryFrame>odom</odometryFrame>

    <!-- Robot frame to calculate odometry from, defaults to `base_footprint` -->
    <robotBaseFrame>base_link</robotBaseFrame>

    <!-- Odometry source, 0 for ENCODER, 1 for WORLD, defaults to WORLD -->
    <odometrySource>1</odometrySource>

    <!-- Set to true to publish transforms for the wheel links, defaults to false -->
    <publishWheelTF>false</publishWheelTF>

    <!-- Set to true to publish transforms for the odometry, defaults to true -->
    <publishOdom>true</publishOdom>

    <!-- Set to true to publish sensor_msgs/JointState on /joint_states for the wheel joints, defaults to false -->
    <publishWheelJointState>false</publishWheelJointState>

    <!-- Set to true to swap right and left wheels, defaults to true -->
    <legacyMode>false</legacyMode>
  </plugin>
</gazebo>

<!-- hokuyo -->
  <gazebo reference="link_5">
    <sensor type="ray" name="head_hokuyo_sensor">
      <pose>0 0 0 0 0 0</pose>
      <visualize>true</visualize>
      <update_rate>20</update_rate>
      <ray>
        <scan>
          <horizontal>
            <samples>720</samples>
            <resolution>1</resolution>
            <min_angle>-3.14</min_angle>
            <max_angle>3.14</max_angle>
          </horizontal>
        </scan>
        <range>
          <min>0.5</min>
          <max>20.0</max>
          <resolution>0.01</resolution>
        </range>
        <noise>
          <type>gaussian</type>
          <!-- Noise parameters based on published spec for Hokuyo laser
               achieving "+-30mm" accuracy at range < 10m.  A mean of 0.0m and
               stddev of 0.01m will put 99.7% of samples within 0.03m of the true
               reading. -->
          <mean>0.0</mean>
          <stddev>0.01</stddev>
        </noise>
      </ray>
        <plugin name="gazebo_ros_head_hokuyo_controller" filename="libgazebo_ros_laser.so">
        <topicName>/scan</topicName>
        <frameName>link_5</frameName>
      </plugin>
    </sensor>
  </gazebo>
  
</robot>
